Workbook

Sheet SAP ABAP Tracker
A1: 📘 SAP ABAP Course – Curriculum Tracker
A2: Course: SAP ABAP Name : Shubham B. Randive Start Date: 30/05/2026 Target Date: 30/06/2026
A3: ✅ Done | 🔄 In Progress | ⏳ Pending Priority: High / Medium / Low Difficulty: Easy / Medium / Hard
A4: Sr | B4: Module / Topic | C4: Important Sub-topics | D4: Status | E4: Date Started | F4: Date Completed | G4: Priority | H4: Difficulty | I4: Notes / Resource Link | J4: Interview Questions
A5: MODULE 1: SAP / ERP Fundamentals
A6: 1 | B6: ERP, SAP & SAP Modules | C6: What is ERP; SAP overview; MM/SD/FI/CO/HR/PP modules | D6: ✅ Done | G6: High | H6: Medium | J6: DONE
A7: 2 | B7: Features of SAP & SAP R/3 Architecture | C7: 3-tier architecture; Presentation/Application/DB layers; Netweaver | D7: ✅ Done | G7: High | H7: Medium
A8: 3 | B8: TR & SAP R/3 Architecture | C8: Transport Request concept; Dev→QA→Prod landscape; CTS | D8: ✅ Done | G8: High | H8: Medium
A9: 4 | B9: Roles of ABAPer | C9: Developer responsibilities; Tickets; Change requests; Performance tuning | D9: ✅ Done | G9: High | H9: Medium
A10: 5 | B10: ABAP Application Server Architecture | C10: Work processes; Dispatcher; Memory management; Buffers | D10: ✅ Done | G10: High | H10: Medium
A11: MODULE 2: ABAP Basics
A12: 6 | B12: ABAP Objects | C12: Data declarations; Operators; Control statements; Loops; Modularisation | D12: ✅ Done | G12: High | H12: Medium
A13: 7 | B13: Header & Item Table | C13: Parent-child table design; Header key; Item key; Joins | D13: ⏳ Pending | G13: High | H13: Medium
A14: 8 | B14: Steps to Create TR | C14: SE09/SE10; Task vs Request; Release process | D14: ✅ Done | G14: High | H14: Medium
A15: 9 | B15: Data Types | C15: Elementary types (C/N/I/F/D/T/P/X); Complex types; Generic types | D15: ⏳ Pending | G15: High | H15: Medium
A16: 10 | B16: RICEFW | C16: Reports; Interfaces; Conversions; Enhancements; Forms; Workflows | D16: ⏳ Pending | G16: High | H16: Medium
A17: MODULE 3: ABAP Dictionary (DDIC)
A18: 11 | B18: ABAP Dictionary & DDIC (SE11) | C18: Domains; Data elements; Transparent/Pooled/Cluster tables; SE11 navigation | D18: 🔄 In Progress | G18: High | H18: Medium
A19: 12 | B19: Domains | C19: Value range; Fixed values; Foreign key check; Domain hierarchy | D19: ⏳ Pending | G19: High | H19: Medium
A20: 13 | B20: Table Creation | C20: Defining fields; Technical settings; Delivery class; Enhancement category | D20: ⏳ Pending | G20: High | H20: Medium
A21: 14 | B21: TMG (Table Maintenance Generator) | C21: SM30; Function group; Authorization group; Recording routine | D21: ⏳ Pending | G21: High | H21: Medium
A22: 15 | B22: PK–FK Relationships | C22: Primary key; Foreign key; Cardinality check; Referential integrity | D22: ⏳ Pending | G22: High | H22: Medium
A23: 16 | B23: Types of DB Tables & Cardinality | C23: Transparent/Pool/Cluster; 1:1, 1:N, N:M cardinality | D23: ⏳ Pending | G23: High | H23: Medium
A24: 17 | B24: Structure | C24: Flat vs nested structures; INCLUDE; Append structures | D24: ⏳ Pending | G24: High | H24: Medium
A25: 18 | B25: Views | C25: Database/Projection/Maintenance/Help views; SE11 view creation | D25: ⏳ Pending | G25: High | H25: Medium
A26: 19 | B26: Index | C26: Primary vs secondary index; Index on custom tables; Performance impact | D26: ⏳ Pending | G26: High | H26: Medium
A27: 20 | B27: Search Help | C27: Elementary & Collective search helps; SE11; Attaching to field | D27: ⏳ Pending | G27: High | H27: Medium
A28: 21 | B28: Table Buffering | C28: Full/Generic/Single-record buffering; When to buffer; Consistency | D28: ⏳ Pending | G28: High | H28: Medium
A29: 22 | B29: Lock Object | C29: SE11 lock objects; Enqueue/Dequeue; Lock modes (S/E/X) | D29: ⏳ Pending | G29: High | H29: Medium
... A31: 24 | B31: DDIC Project | C31: End-to-end DDIC object creation exercise | D31: ⏳ Pending | G31: High | H31: Medium
A32: MODULE 4: ABAP Programming
A33: 25 | B33: ABAP Programming – Variant | C33: SE38; Program types; Variants; SY- system variables | D33: ⏳ Pending | G33: High | H33: Medium
A34: 26 | B34: Internal Table & Work Area | C34: TYPES; DATA; LIKE LINE OF; Header line vs work area; OCCURS | D34: ⏳ Pending | G34: High | H34: Medium
A35: 27 | B35: Internal Table Operations | C35: APPEND/INSERT/MODIFY/DELETE/READ/LOOP/SORT; Binary search | D35: ⏳ Pending | G35: High | H35: Medium
A36: 28 | B36: Selection Screen | C36: PARAMETERS; SELECT-OPTIONS; SELECTION-SCREEN blocks; AT SELECTION-SCREEN | D36: ⏳ Pending | G36: High | H36: Medium
A37: 29 | B37: Reports | C37: Classical/Interactive/ALV reports; Events; WRITE statement | D37: ⏳ Pending | G37: High | H37: Medium
A38: 30 | B38: Joins (Open SQL) | C38: INNER/LEFT OUTER JOIN; FOR ALL ENTRIES; Subquery; Performance tips | D38: ⏳ Pending | G38: High | H38: Medium
A39: 31 | B39: Message Class | C39: SE91; Message types (A/E/I/S/W/X); MESSAGE statement | D39: ⏳ Pending | G39: High | H39: Medium
A40: MODULE 5: Reports
A41: 32 | B41: Classical Report Events | C41: INITIALIZATION; START-OF-SELECTION; END-OF-SELECTION; TOP-OF-PAGE; END-OF-PAGE | D41: ⏳ Pending | G41: High | H41: Medium
...

Sheet Dashboard
A1: 📊 SAP ABAP Course – Progress Dashboard
A2: Metric | B2: Count | C2: Progress Bar (out of 20)
A3: ✅ Completed Topics | B3: =COUNTIF('SAP ABAP Tracker'!D:D,"✅ Done") -> 7 | C3: =REPT("█",ROUND(B3/B6*20,0))&REPT("░",20-ROUND(B3/B6*20,0)) -> ██░░░░░░░░░░░░░░░░░░
A4: 🔄 In Progress Topics | B4: =COUNTIF('SAP ABAP Tracker'!D:D,"🔄 In Progress") -> 1
A5: ⏳ Pending Topics | B5: =COUNTIF('SAP ABAP Tracker'!D:D,"⏳ Pending") -> 54
A6: 📚 Total Topics | B6: =B3+B4+B5 -> 62
A9: Module-wise Progress
A10: Module | B10: Total | C10: Done | D10: In Progress | E10: Pending
A11: SAP / ERP Fundamentals | B11: 5 | C11: =COUNTIFS('SAP ABAP Tracker'!B:B,"*SAP*",'SAP ABAP Tracker'!D:D,"✅ Done") -> 3 | D11: =COUNTIFS('SAP ABAP Tracker'!B:B,"*SAP*",'SAP ABAP Tracker'!D:D,"🔄 In Progress") -> 0 | E11: =COUNTIFS('SAP ABAP Tracker'!B:B,"*SAP*",'SAP ABAP Tracker'!D:D,"⏳ Pending") -> 0
A12: ABAP Basics | B12: 5 | C12: =COUNTIFS('SAP ABAP Tracker'!B:B,"*ABAP*",'SAP ABAP Tracker'!D:D,"✅ Done") -> 3 | D12: =COUNTIFS('SAP ABAP Tracker'!B:B,"*ABAP*",'SAP ABAP Tracker'!D:D,"🔄 In Progress") -> 1 | E12: =COUNTIFS('SAP ABAP Tracker'!B:B,"*ABAP*",'SAP ABAP Tracker'!D:D,"⏳ Pending") -> 3
A13: ABAP Dictionary (DDIC) | B13: 14 | C13: =COUNTIFS('SAP ABAP Tracker'!B:B,"*ABAP*",'SAP ABAP Tracker'!D:D,"✅ Done") -> 3 | D13: =COUNTIFS('SAP ABAP Tracker'!B:B,"*ABAP*",'SAP ABAP Tracker'!D:D,"🔄 In Progress") -> 1 | E13: =COUNTIFS('SAP ABAP Tracker'!B:B,"*ABAP*",'SAP ABAP Tracker'!D:D,"⏳ Pending") -> 3
A14: ABAP Programming | B14: 7 | C14: =COUNTIFS('SAP ABAP Tracker'!B:B,"*ABAP*",'SAP ABAP Tracker'!D:D,"✅ Done") -> 3 | D14: =COUNTIFS('SAP ABAP Tracker'!B:B,"*ABAP*",'SAP ABAP Tracker'!D:D,"🔄 In Progress") -> 1 | E14: =COUNTIFS('SAP ABAP Tracker'!B:B,"*ABAP*",'SAP ABAP Tracker'!D:D,"⏳ Pending") -> 3
A15: Reports | B15: 4 | C15: =COUNTIFS('SAP ABAP Tracker'!B:B,"*Reports*",'SAP ABAP Tracker'!D:D,"✅ Done") -> 0 | D15: =COUNTIFS('SAP ABAP Tracker'!B:B,"*Reports*",'SAP ABAP Tracker'!D:D,"🔄 In Progress") -> 0 | E15: =COUNTIFS('SAP ABAP Tracker'!B:B,"*Reports*",'SAP ABAP Tracker'!D:D,"⏳ Pending") -> 1
A16: Modularisation & OOP | B16: 11 | C16: =COUNTIFS('SAP ABAP Tracker'!B:B,"*Modularisation*",'SAP ABAP Tracker'!D:D,"✅ Done") -> 0 | D16: =COUNTIFS('SAP ABAP Tracker'!B:B,"*Modularisation*",'SAP ABAP Tracker'!D:D,"🔄 In Progress") -> 0 | E16: =COUNTIFS('SAP ABAP Tracker'!B:B,"*Modularisation*",'SAP ABAP Tracker'!D:D,"⏳ Pending") -> 1
A17: BAPI | B17: 7 | C17: =COUNTIFS('SAP ABAP Tracker'!B:B,"*BAPI*",'SAP ABAP Tracker'!D:D,"✅ Done") -> 0 | D17: =COUNTIFS('SAP ABAP Tracker'!B:B,"*BAPI*",'SAP ABAP Tracker'!D:D,"🔄 In Progress") -> 0 | E17: =COUNTIFS('SAP ABAP Tracker'!B:B,"*BAPI*",'SAP ABAP Tracker'!D:D,"⏳ Pending") -> 7
A18: Enhancement | B18: 9 | C18: =COUNTIFS('SAP ABAP Tracker'!B:B,"*Enhancement*",'SAP ABAP Tracker'!D:D,"✅ Done") -> 0 | D18: =COUNTIFS('SAP ABAP Tracker'!B:B,"*Enhancement*",'SAP ABAP Tracker'!D:D,"🔄 In Progress") -> 0 | E18: =COUNTIFS('SAP ABAP Tracker'!B:B,"*Enhancement*",'SAP ABAP Tracker'!D:D,"⏳ Pending") -> 5
A20: 💡 Update Status in 'SAP ABAP Tracker' sheet — Dashboard recalculates automatically!

Sheet How To Use
A1: 📖 How To Use This SAP ABAP Tracker
A2: STEP / FEATURE | B2: DETAILS
A3: 1️⃣ Update Status | B3: Click any cell in the 'Status' column → choose from dropdown: ✅ Done | 🔄 In Progress | ⏳ Pending
A4: 2️⃣ Fill Dates | B4: Enter 'Date Started' when you begin a topic. Enter 'Date Completed' once finished. Format: DD-Mon-YYYY (e.g. 05-Jun-2025)
A5: 3️⃣ Set Priority | B5: Use Priority dropdown (High / Medium / Low) to plan your study sequence.
A6: 4️⃣ Set Difficulty | B6: Mark each topic as Easy / Medium / Hard to gauge your revision effort.
A7: 5️⃣ Notes Column | B7: Add YouTube links, book chapter refs, practice tcode names, or personal notes.
A8: 6️⃣ Dashboard Sheet | B8: Switch to 'Dashboard' to see total Done/In-Progress/Pending counts and % — auto-updates!
A9: 7️⃣ Module Headers | B9: Dark rows = Module headers (not editable). Light rows = individual topics.
A10: 8️⃣ Adding Topics | B10: Insert a new row inside the module block, copy formatting from adjacent row, fill details.
A11: 9️⃣ BAPI Module | B11: Covers BAPI architecture, calling BAPIs, BAPIRET2 error handling, and custom BAPI creation.
A12: 🔟 Enhancement Module | B12: Covers User Exits (SMOD/CMOD), BADIs (SE18/SE19), Enhancement Framework, Pre/Post hooks.
A13: 🎨 Color Guide | B13: 🟢 Green = Done 🔵 Blue = In Progress 🟡 Yellow = Pending ⬛ Dark Blue = Module Header
